Workbook

Sheet Сводка
A1: Эллинг «Застава», посёлок «Берта» — полная стоимость, ₽ с НДС (IV кв. 2026)
A2: Площадь помещений 961.54 м²; цены Москва/МО под ключ; формулы живые — меняйте цены на листах сценариев
A4: Показатель | B4: A — проект ЭП как есть | C4: B — рекомендуемый | D4: C — минимум первой очереди
A5: СМР здания | B5: ='Смета A'!H79 | C5: ='Смета B'!H79 | D5: ='Смета C'!H79
A6: Вне СМР | B6: =SUM('Вне СМР'!C2:C16) | C6: =SUM('Вне СМР'!D2:D16) | D6: =SUM('Вне СМР'!E2:E16)
A7: Резерв, доля | B7: 0.15 | C7: 0.12 | D7: 0.15
A8: Резерв | B8: =(B5+B6)*B7 | C8: =(C5+C6)*C7 | D8: =(D5+D6)*D7
A9: ПОЛНАЯ СТОИМОСТЬ | B9: =B5+B6+B8 | C9: =C5+C6+C8 | D9: =D5+D6+D8
A10: СМР, ₽/м² | B10: =B5/961.54 | C10: =C5/961.54 | D10: =D5/961.54
A11: Полная, ₽/м² | B11: =B9/961.54 | C11: =C9/961.54 | D11: =D9/961.54
A13: Справочно | B13: До резерва | C13: С резервом | D13: ₽/м²
A14: Смета ЭП (вариант 2 ЖБ) | B14: 141200000 | C14: 155320000 | D14: 161020
A15: Модель Строй Хауз (× 43,5/31,36) | B15: 195860969 | D15: 203049

Sheet Смета A
A1: Раздел | B1: Наименование | C1: Ед. | D1: Кол-во | E1: Цена, ₽/ед. | F1: Материалы, ₽ | G1: Работы, ₽ | H1: Сумма, ₽ | I1: Основание
A2: 01 Подготовка территории | B2: Бытовки, временные сети, ограждение, охрана на период стройки | C2: мес | D2: 12 | E2: 120000 | F2: =H2*0.3 | G2: =H2-F2 | H2: =D2*E2 | I2: общая площадка посёлка — рычаг 7
A3: 01 Подготовка территории | B3: Геодезическая разбивка и исполнительные съёмки | C3: компл | D3: 1 | E3: 250000 | F3: =H3*0.0 | G3: =H3-F3 | H3: =D3*E3 | I3: рынок МО
A4: 01 Подготовка территории | B4: Вывоз мусора, уборка площадки | C4: мес | D4: 12 | E4: 35000 | F4: =H4*0.2 | G4: =H4-F4 | H4: =D4*E4 | I4: рынок МО
A5: 02 Земляные работы | B5: Срезка растительного слоя и глины 0,3 м с вывозом | C5: м³ | D5: 208 | E5: 1300 | F5: =H5*0.0 | G5: =H5-F5 | H5: =D5*E5 | I5: вывоз 700 ₽/м³ (протокол 19.10) + разработка
A6: 02 Земляные работы | B6: Песчаная подушка 0,5 м с послойным уплотнением | C6: м³ | D6: 308 | E6: 1900 | F6: =H6*0.65 | G6: =H6-F6 | H6: =D6*E6 | I6: песок 900–1 100 ₽/м³
A7: 02 Земляные работы | B7: Обратная засыпка пазух, планировка | C7: м³ | D7: 180 | E7: 900 | F7: =H7*0.4 | G7: =H7-F7 | H7: =D7*E7 | I7: рынок МО
A8: 03 Фундамент | B8: Сваи ЖБ С80.30 (8 м) с забивкой, 77 шт. | C8: шт | D8: 77 | E8: 34000 | F8: =H8*0.65 | G8: =H8-F8 | H8: =D8*E8 | I8: свая 19–21 тыс. + забивка 1 200–1 500 ₽/м
A9: 03 Фундамент | B9: Испытания свай статической и динамической нагрузкой | C9: компл | D9: 1 | E9: 350000 | F9: =H9*0.0 | G9: =H9-F9 | H9: =D9*E9 | I9: СП 24.13330
A10: 03 Фундамент | B10: Подбетонка В7,5 80 мм | C10: м² | D10: 513.57 | E10: 750 | F10: =H10*0.6 | G10: =H10-F10 | H10: =D10*E10 | I10: рынок МО
A11: 03 Фундамент | B11: Гидроизоляция под плиту и по торцам (2 слоя наплавляемая) | C11: м² | D11: 591 | E11: 1100 | F11: =H11*0.55 | G11: =H11-F11 | H11: =D11*E11 | I11: у воды — без экономии
A12: 03 Фундамент | B12: ЭППС 100 мм под плитой и по периметру | C12: м² | D12: 565 | E12: 1300 | F12: =H12*0.75 | G12: =H12-F12 | H12: =D12*E12 | I12: рынок МО
A13: 03 Фундамент | B13: Монолитная плита 300 мм на сваях, В25 W8 F150, А500 ≈ 115 кг/м³ (пол 1 этажа) | C13: м³ | D13: 154.1 | E13: 27000 | F13: =H13*0.62 | G13: =H13-F13 | H13: =D13*E13 | I13: бетон 8–8,5 тыс./м³, арматура 85 тыс./т, работы 7–9 тыс./м³
A14: 03 Фундамент | B14: Цокольное перекрытие (в ЭП-смете отдельно 4,0 млн; при плите на сваях не нужно) | C14: м² | D14: 513.57 | E14: 7800 | F14: =H14*0.6 | G14: =H14-F14 | H14: =D14*E14 | I14: дублирование в смете ЭП — исключено в B/C
A15: 03 Фундамент | B15: Закладные, гильзы, выпуски (по ведомости закладных) | C15: компл | D15: 1 | E15: 350000 | F15: =H15*0.5 | G15: =H15-F15 | H15: =D15*E15 | I15: аналог БР-ЗК
A16: 04 Каркас и перекрытия | B16: Колонны 1 этажа: стальные с огнезащитой R150 (A) / монолит ЖБ 400×400 (B, C) | C16: шт | D16: 14 | E16: 210000 | F16: =H16*0.55 | G16: =H16-F16 | H16: =D16*E16 | I16: R150 для стали — 1,5–3 тыс./м² поверхности; ЖБ обеспечивает сам
A17: 04 Каркас и перекрытия | B17: Межэтажное и под плоскую кровлю: монолит ЖБ плита 200 + рёбра 600 (A, B) / ПБ + монолитные участки (C) | C17: м² | D17: 798.74 | E17: 11500 | F17: =H17*0.55 | G17: =H17-F17 | H17: =D17*E17 | I17: монолит 10,5–12,5 тыс.; ПБ 5,5–7 тыс.
A18: 04 Каркас и перекрытия | B18: Зимнее бетонирование (прогрев, тепляк) — если перекрытие попадает на ноябрь–март | C18: м² | D18: 798.74 | E18: 900 | F18: =H18*0.3 | G18: =H18-F18 | H18: =D18*E18 | I18: B, C — бетонирование в тёплый сезон по ПОС
A19: 04 Каркас и перекрытия | B19: Армопояса, перемычки, монолитные участки | C19: м³ | D19: 40 | E19: 32000 | F19: =H19*0.55 | G19: =H19-F19 | H19: =D19*E19 | I19: рынок МО
A20: 04 Каркас и перекрытия | B20: Монолитная лестница 012 с ограждением | C20: компл | D20: 1 | E20: 650000 | F20: =H20*0.5 | G20: =H20-F20 | H20: =D20*E20 | I20: 1 лестница 2 марша
A21: 05 Стены и перегородки | B21: Наружные стены газобетон D500 400 мм (блок, клей, армирование, кладка) | C21: м³ | D21: 309.14 | E21: 13500 | F21: =H21*0.6 | G21: =H21-F21 | H21: =D21*E21 | I21: рынок 11,5–15,5 тыс.
A22: 05 Стены и перегородки | B22: Внутренние стены газобетон 300 мм | C22: м³ | D22: 153.54 | E22: 13500 | F22: =H22*0.6 | G22: =H22-F22 | H22: =D22*E22 | I22: рынок 11,5–15,5 тыс.
A23: 05 Стены и перегородки | B23: Перегородки газобетон 150 мм | C23: м³ | D23: 57.47 | E23: 15000 | F23: =H23*0.6 | G23: =H23-F23 | H23: =D23*E23 | I23: мелкий блок дороже на м³
A24: 05 Стены и перегородки | B24: Противопожарные стены гараж/лестница, тамбур-шлюз (EI 150, двери EI 60) | C24: компл | D24: 1 | E24: 450000 | F24: =H24*0.6 | G24: =H24-F24 | H24: =D24*E24 | I24: СП 4.13130 — требование раздела ПБ
A25: 06 Кровля | B25: Чердачное перекрытие деревянное утеплённое 250 мм | C25: м² | D25: 473.73 | E25: 7200 | F25: =H25*0.6 | G25: =H25-F25 | H25: =D25*E25 | I25: рынок 6–8,5 тыс.
A26: 06 Кровля | B26: Скатная кровля: стропила, ОСП, мембраны, кликфальц, водосток, снегозадержание | C26: м² | D26: 570.93 | E26: 11500 | F26: =H26*0.6 | G26: =H26-F26 | H26: =D26*E26 | I26: рынок 9–13 тыс.; СХ 19,6 тыс.
A27: 06 Кровля | B27: Плоская кровля: эксплуатируемая (A, B) / неэксплуатируемая (C) | C27: м² | D27: 233.34 | E27: 13300 | F27: =H27*0.6 | G27: =H27-F27 | H27: =D27*E27 | I27: рынок 9–16 тыс.
A28: 06 Кровля | B28: Каркасные фронтоны | C28: м² | D28: 186.21 | E28: 5500 | F28: =H28*0.6 | G28: =H28-F28 | H28: =D28*E28 | I28: рынок МО
A29: 07 Фасады | B29: Утепление вентфасада минвата 100 мм + ветрозащита + подсистема | C29: м² | D29: 1310 | E29: 2600 | F29: =H29*0.55 | G29: =H29-F29 | H29: =D29*E29 | I29: подсистема 1,2–1,5 + утеплитель 1,0
A30: 07 Фасады | B30: Облицовка натуральным сланцем (A 490 м²; B, C — акцент 150 м²) | C30: м² | D30: 490 | E30: 10500 | F30: =H30*0.6 | G30: =H30-F30 | H30: =D30*E30 | I30: рынок 8–13 тыс.
A31: 07 Фасады | B31: Облицовка сланцем — акцентные плоскости (вход, торец к воде) | C31: м² | D31: 150 | E31: 0 | F31: =H31*0.6 | G31: =H31-F31 | H31: =D31*E31 | I31: рычаг 3
A32: 07 Фасады | B32: Планкен лиственница с обработкой (A 600 м²; B, C — 940 м²) | C32: м² | D32: 600 | E32: 6500 | F32: =H32*0.6 | G32: =H32-F32 | H32: =D32*E32 | I32: рынок 6,4–9,9 тыс.
A33: 07 Фасады | B33: Планкен лиственница с обработкой — основной материал | C33: м² | D33: 940 | E33: 0 | F33: =H33*0.6 | G33: =H33-F33 | H33: =D33*E33 | I33: рычаг 3
A34: 07 Фасады | B34: Фасадный фальц | C34: м² | D34: 220 | E34: 6500 | F34: =H34*0.6 | G34: =H34-F34 | H34: =D34*E34 | I34: рынок 4,5–7,5 тыс.
A35: 07 Фасады | B35: Цоколь: облицовка, отмостка 1,0 м с утеплением | C35: м.п. | D35: 104 | E35: 9000 | F35: =H35*0.55 | G35: =H35-F35 | H35: =D35*E35 | I35: периметр ≈ 104 м
A36: 08 Окна, витражи, ворота | B36: Тёплые алюминиевые витражи: Schüco-уровень (A) / Alutech W72 (B, C) | C36: м² | D36: 170.64 | E36: 33000 | F36: =H36*0.75 | G36: =H36-F36 | H36: =D36*E36 | I36: Alutech под ключ 19–27 тыс.
A37: 08 Окна, витражи, ворота | B37: Окна ПВХ (Rehau/Veka класс А, R 0,8) | C37: м² | D37: 60 | E37: 20000 | F37: =H37*0.75 | G37: =H37-F37 | H37: =D37*E37 | I37: рынок 12–18 тыс.
A38: 08 Окна, витражи, ворота | B38: Откосы, отливы, подоконники | C38: м² | D38: 230.64 | E38: 2500 | F38: =H38*0.5 | G38: =H38-F38 | H38: =D38*E38 | I38: рынок МО
A39: 08 Окна, витражи, ворота | B39: Ворота гаражные секционные утеплённые с автоматикой 3.5×2.6 м | C39: шт | D39: 8 | E39: 260000 | F39: =H39*0.85 | G39: =H39-F39 | H39: =D39*E39 | I39: Doorhan/Alutech с приводом
A40: 08 Окна, витражи, ворота | B40: Ворота эллинга подъёмно-секционные (под катер на прицепе) 4.5×3.6 м | C40: шт | D40: 1 | E40: 650000 | F40: =H40*0.85 | G40: =H40-F40 | H40: =D40*E40 | I40: нестандарт, усиленный привод
...

Sheet Смета B
A1: Раздел | B1: Наименование | C1: Ед. | D1: Кол-во | E1: Цена, ₽/ед. | F1: Материалы, ₽ | G1: Работы, ₽ | H1: Сумма, ₽ | I1: Основание
A2: 01 Подготовка территории | B2: Бытовки, временные сети, ограждение, охрана на период стройки | C2: мес | D2: 12 | E2: 70000 | F2: =H2*0.3 | G2: =H2-F2 | H2: =D2*E2 | I2: общая площадка посёлка — рычаг 7
A3: 01 Подготовка территории | B3: Геодезическая разбивка и исполнительные съёмки | C3: компл | D3: 1 | E3: 220000 | F3: =H3*0.0 | G3: =H3-F3 | H3: =D3*E3 | I3: рынок МО
A4: 01 Подготовка территории | B4: Вывоз мусора, уборка площадки | C4: мес | D4: 12 | E4: 30000 | F4: =H4*0.2 | G4: =H4-F4 | H4: =D4*E4 | I4: рынок МО
A5: 02 Земляные работы | B5: Срезка растительного слоя и глины 0,3 м с вывозом | C5: м³ | D5: 208 | E5: 1100 | F5: =H5*0.0 | G5: =H5-F5 | H5: =D5*E5 | I5: вывоз 700 ₽/м³ (протокол 19.10) + разработка
A6: 02 Земляные работы | B6: Песчаная подушка 0,5 м с послойным уплотнением | C6: м³ | D6: 308 | E6: 1700 | F6: =H6*0.65 | G6: =H6-F6 | H6: =D6*E6 | I6: песок 900–1 100 ₽/м³
A7: 02 Земляные работы | B7: Обратная засыпка пазух, планировка | C7: м³ | D7: 180 | E7: 800 | F7: =H7*0.4 | G7: =H7-F7 | H7: =D7*E7 | I7: рынок МО
A8: 03 Фундамент | B8: Сваи ЖБ С80.30 (8 м) с забивкой, 77 шт. | C8: шт | D8: 77 | E8: 31000 | F8: =H8*0.65 | G8: =H8-F8 | H8: =D8*E8 | I8: свая 19–21 тыс. + забивка 1 200–1 500 ₽/м
A9: 03 Фундамент | B9: Испытания свай статической и динамической нагрузкой | C9: компл | D9: 1 | E9: 300000 | F9: =H9*0.0 | G9: =H9-F9 | H9: =D9*E9 | I9: СП 24.13330
A10: 03 Фундамент | B10: Подбетонка В7,5 80 мм | C10: м² | D10: 513.57 | E10: 700 | F10: =H10*0.6 | G10: =H10-F10 | H10: =D10*E10 | I10: рынок МО
A11: 03 Фундамент | B11: Гидроизоляция под плиту и по торцам (2 слоя наплавляемая) | C11: м² | D11: 591 | E11: 950 | F11: =H11*0.55 | G11: =H11-F11 | H11: =D11*E11 | I11: у воды — без экономии
A12: 03 Фундамент | B12: ЭППС 100 мм под плитой и по периметру | C12: м² | D12: 565 | E12: 1200 | F12: =H12*0.75 | G12: =H12-F12 | H12: =D12*E12 | I12: рынок МО
A13: 03 Фундамент | B13: Монолитная плита 300 мм на сваях, В25 W8 F150, А500 ≈ 115 кг/м³ (пол 1 этажа) | C13: м³ | D13: 154.1 | E13: 25000 | F13: =H13*0.62 | G13: =H13-F13 | H13: =D13*E13 | I13: бетон 8–8,5 тыс./м³, арматура 85 тыс./т, работы 7–9 тыс./м³
A14: 03 Фундамент | B14: Цокольное перекрытие (в ЭП-смете отдельно 4,0 млн; при плите на сваях не нужно) | C14: м² | D14: 513.57 | E14: 0 | F14: =H14*0.6 | G14: =H14-F14 | H14: =D14*E14 | I14: дублирование в смете ЭП — исключено в B/C
A15: 03 Фундамент | B15: Закладные, гильзы, выпуски (по ведомости закладных) | C15: компл | D15: 1 | E15: 300000 | F15: =H15*0.5 | G15: =H15-F15 | H15: =D15*E15 | I15: аналог БР-ЗК
A16: 04 Каркас и перекрытия | B16: Колонны 1 этажа: стальные с огнезащитой R150 (A) / монолит ЖБ 400×400 (B, C) | C16: шт | D16: 14 | E16: 65000 | F16: =H16*0.55 | G16: =H16-F16 | H16: =D16*E16 | I16: R150 для стали — 1,5–3 тыс./м² поверхности; ЖБ обеспечивает сам
A17: 04 Каркас и перекрытия | B17: Межэтажное и под плоскую кровлю: монолит ЖБ плита 200 + рёбра 600 (A, B) / ПБ + монолитные участки (C) | C17: м² | D17: 798.74 | E17: 11500 | F17: =H17*0.55 | G17: =H17-F17 | H17: =D17*E17 | I17: монолит 10,5–12,5 тыс.; ПБ 5,5–7 тыс.
A18: 04 Каркас и перекрытия | B18: Зимнее бетонирование (прогрев, тепляк) — если перекрытие попадает на ноябрь–март | C18: м² | D18: 798.74 | E18: 0 | F18: =H18*0.3 | G18: =H18-F18 | H18: =D18*E18 | I18: B, C — бетонирование в тёплый сезон по ПОС
A19: 04 Каркас и перекрытия | B19: Армопояса, перемычки, монолитные участки | C19: м³ | D19: 40 | E19: 30000 | F19: =H19*0.55 | G19: =H19-F19 | H19: =D19*E19 | I19: рынок МО
A20: 04 Каркас и перекрытия | B20: Монолитная лестница 012 с ограждением | C20: компл | D20: 1 | E20: 600000 | F20: =H20*0.5 | G20: =H20-F20 | H20: =D20*E20 | I20: 1 лестница 2 марша
A21: 05 Стены и перегородки | B21: Наружные стены газобетон D500 400 мм (блок, клей, армирование, кладка) | C21: м³ | D21: 309.14 | E21: 13000 | F21: =H21*0.6 | G21: =H21-F21 | H21: =D21*E21 | I21: рынок 11,5–15,5 тыс.
A22: 05 Стены и перегородки | B22: Внутренние стены газобетон 300 мм | C22: м³ | D22: 153.54 | E22: 13000 | F22: =H22*0.6 | G22: =H22-F22 | H22: =D22*E22 | I22: рынок 11,5–15,5 тыс.
A23: 05 Стены и перегородки | B23: Перегородки газобетон 150 мм | C23: м³ | D23: 57.47 | E23: 14000 | F23: =H23*0.6 | G23: =H23-F23 | H23: =D23*E23 | I23: мелкий блок дороже на м³
A24: 05 Стены и перегородки | B24: Противопожарные стены гараж/лестница, тамбур-шлюз (EI 150, двери EI 60) | C24: компл | D24: 1 | E24: 450000 | F24: =H24*0.6 | G24: =H24-F24 | H24: =D24*E24 | I24: СП 4.13130 — требование раздела ПБ
A25: 06 Кровля | B25: Чердачное перекрытие деревянное утеплённое 250 мм | C25: м² | D25: 473.73 | E25: 7000 | F25: =H25*0.6 | G25: =H25-F25 | H25: =D25*E25 | I25: рынок 6–8,5 тыс.
A26: 06 Кровля | B26: Скатная кровля: стропила, ОСП, мембраны, кликфальц, водосток, снегозадержание | C26: м² | D26: 570.93 | E26: 11000 | F26: =H26*0.6 | G26: =H26-F26 | H26: =D26*E26 | I26: рынок 9–13 тыс.; СХ 19,6 тыс.
A27: 06 Кровля | B27: Плоская кровля: эксплуатируемая (A, B) / неэксплуатируемая (C) | C27: м² | D27: 233.34 | E27: 12500 | F27: =H27*0.6 | G27: =H27-F27 | H27: =D27*E27 | I27: рынок 9–16 тыс.
A28: 06 Кровля | B28: Каркасные фронтоны | C28: м² | D28: 186.21 | E28: 5500 | F28: =H28*0.6 | G28: =H28-F28 | H28: =D28*E28 | I28: рынок МО
A29: 07 Фасады | B29: Утепление вентфасада минвата 100 мм + ветрозащита + подсистема | C29: м² | D29: 1310 | E29: 2400 | F29: =H29*0.55 | G29: =H29-F29 | H29: =D29*E29 | I29: подсистема 1,2–1,5 + утеплитель 1,0
A30: 07 Фасады | B30: Облицовка натуральным сланцем (A 490 м²; B, C — акцент 150 м²) | C30: м² | D30: 490 | E30: 0 | F30: =H30*0.6 | G30: =H30-F30 | H30: =D30*E30 | I30: рынок 8–13 тыс.
A31: 07 Фасады | B31: Облицовка сланцем — акцентные плоскости (вход, торец к воде) | C31: м² | D31: 150 | E31: 10500 | F31: =H31*0.6 | G31: =H31-F31 | H31: =D31*E31 | I31: рычаг 3
A32: 07 Фасады | B32: Планкен лиственница с обработкой (A 600 м²; B, C — 940 м²) | C32: м² | D32: 600 | E32: 0 | F32: =H32*0.6 | G32: =H32-F32 | H32: =D32*E32 | I32: рынок 6,4–9,9 тыс.
A33: 07 Фасады | B33: Планкен лиственница с обработкой — основной материал | C33: м² | D33: 940 | E33: 6300 | F33: =H33*0.6 | G33: =H33-F33 | H33: =D33*E33 | I33: рычаг 3
A34: 07 Фасады | B34: Фасадный фальц | C34: м² | D34: 220 | E34: 5500 | F34: =H34*0.6 | G34: =H34-F34 | H34: =D34*E34 | I34: рынок 4,5–7,5 тыс.
A35: 07 Фасады | B35: Цоколь: облицовка, отмостка 1,0 м с утеплением | C35: м.п. | D35: 104 | E35: 8000 | F35: =H35*0.55 | G35: =H35-F35 | H35: =D35*E35 | I35: периметр ≈ 104 м
A36: 08 Окна, витражи, ворота | B36: Тёплые алюминиевые витражи: Schüco-уровень (A) / Alutech W72 (B, C) | C36: м² | D36: 170.64 | E36: 23000 | F36: =H36*0.75 | G36: =H36-F36 | H36: =D36*E36 | I36: Alutech под ключ 19–27 тыс.
A37: 08 Окна, витражи, ворота | B37: Окна ПВХ (Rehau/Veka класс А, R 0,8) | C37: м² | D37: 60 | E37: 15000 | F37: =H37*0.75 | G37: =H37-F37 | H37: =D37*E37 | I37: рынок 12–18 тыс.
A38: 08 Окна, витражи, ворота | B38: Откосы, отливы, подоконники | C38: м² | D38: 230.64 | E38: 2000 | F38: =H38*0.5 | G38: =H38-F38 | H38: =D38*E38 | I38: рынок МО
A39: 08 Окна, витражи, ворота | B39: Ворота гаражные секционные утеплённые с автоматикой 3.5×2.6 м | C39: шт | D39: 8 | E39: 220000 | F39: =H39*0.85 | G39: =H39-F39 | H39: =D39*E39 | I39: Doorhan/Alutech с приводом
A40: 08 Окна, витражи, ворота | B40: Ворота эллинга подъёмно-секционные (под катер на прицепе) 4.5×3.6 м | C40: шт | D40: 1 | E40: 520000 | F40: =H40*0.85 | G40: =H40-F40 | H40: =D40*E40 | I40: нестандарт, усиленный привод
...

Sheet Смета C
A1: Раздел | B1: Наименование | C1: Ед. | D1: Кол-во | E1: Цена, ₽/ед. | F1: Материалы, ₽ | G1: Работы, ₽ | H1: Сумма, ₽ | I1: Основание
A2: 01 Подготовка территории | B2: Бытовки, временные сети, ограждение, охрана на период стройки | C2: мес | D2: 12 | E2: 70000 | F2: =H2*0.3 | G2: =H2-F2 | H2: =D2*E2 | I2: общая площадка посёлка — рычаг 7
A3: 01 Подготовка территории | B3: Геодезическая разбивка и исполнительные съёмки | C3: компл | D3: 1 | E3: 220000 | F3: =H3*0.0 | G3: =H3-F3 | H3: =D3*E3 | I3: рынок МО
A4: 01 Подготовка территории | B4: Вывоз мусора, уборка площадки | C4: мес | D4: 12 | E4: 30000 | F4: =H4*0.2 | G4: =H4-F4 | H4: =D4*E4 | I4: рынок МО
A5: 02 Земляные работы | B5: Срезка растительного слоя и глины 0,3 м с вывозом | C5: м³ | D5: 208 | E5: 1100 | F5: =H5*0.0 | G5: =H5-F5 | H5: =D5*E5 | I5: вывоз 700 ₽/м³ (протокол 19.10) + разработка
A6: 02 Земляные работы | B6: Песчаная подушка 0,5 м с послойным уплотнением | C6: м³ | D6: 308 | E6: 1700 | F6: =H6*0.65 | G6: =H6-F6 | H6: =D6*E6 | I6: песок 900–1 100 ₽/м³
A7: 02 Земляные работы | B7: Обратная засыпка пазух, планировка | C7: м³ | D7: 180 | E7: 800 | F7: =H7*0.4 | G7: =H7-F7 | H7: =D7*E7 | I7: рынок МО
A8: 03 Фундамент | B8: Сваи ЖБ С80.30 (8 м) с забивкой, 77 шт. | C8: шт | D8: 77 | E8: 31000 | F8: =H8*0.65 | G8: =H8-F8 | H8: =D8*E8 | I8: свая 19–21 тыс. + забивка 1 200–1 500 ₽/м
A9: 03 Фундамент | B9: Испытания свай статической и динамической нагрузкой | C9: компл | D9: 1 | E9: 300000 | F9: =H9*0.0 | G9: =H9-F9 | H9: =D9*E9 | I9: СП 24.13330
A10: 03 Фундамент | B10: Подбетонка В7,5 80 мм | C10: м² | D10: 513.57 | E10: 700 | F10: =H10*0.6 | G10: =H10-F10 | H10: =D10*E10 | I10: рынок МО
A11: 03 Фундамент | B11: Гидроизоляция под плиту и по торцам (2 слоя наплавляемая) | C11: м² | D11: 591 | E11: 950 | F11: =H11*0.55 | G11: =H11-F11 | H11: =D11*E11 | I11: у воды — без экономии
A12: 03 Фундамент | B12: ЭППС 100 мм под плитой и по периметру | C12: м² | D12: 565 | E12: 1200 | F12: =H12*0.75 | G12: =H12-F12 | H12: =D12*E12 | I12: рынок МО
A13: 03 Фундамент | B13: Монолитная плита 300 мм на сваях, В25 W8 F150, А500 ≈ 115 кг/м³ (пол 1 этажа) | C13: м³ | D13: 154.1 | E13: 25000 | F13: =H13*0.62 | G13: =H13-F13 | H13: =D13*E13 | I13: бетон 8–8,5 тыс./м³, арматура 85 тыс./т, работы 7–9 тыс./м³
A14: 03 Фундамент | B14: Цокольное перекрытие (в ЭП-смете отдельно 4,0 млн; при плите на сваях не нужно) | C14: м² | D14: 513.57 | E14: 0 | F14: =H14*0.6 | G14: =H14-F14 | H14: =D14*E14 | I14: дублирование в смете ЭП — исключено в B/C
A15: 03 Фундамент | B15: Закладные, гильзы, выпуски (по ведомости закладных) | C15: компл | D15: 1 | E15: 300000 | F15: =H15*0.5 | G15: =H15-F15 | H15: =D15*E15 | I15: аналог БР-ЗК
A16: 04 Каркас и перекрытия | B16: Колонны 1 этажа: стальные с огнезащитой R150 (A) / монолит ЖБ 400×400 (B, C) | C16: шт | D16: 14 | E16: 65000 | F16: =H16*0.55 | G16: =H16-F16 | H16: =D16*E16 | I16: R150 для стали — 1,5–3 тыс./м² поверхности; ЖБ обеспечивает сам
A17: 04 Каркас и перекрытия | B17: Межэтажное и под плоскую кровлю: монолит ЖБ плита 200 + рёбра 600 (A, B) / ПБ + монолитные участки (C) | C17: м² | D17: 798.74 | E17: 6800 | F17: =H17*0.55 | G17: =H17-F17 | H17: =D17*E17 | I17: монолит 10,5–12,5 тыс.; ПБ 5,5–7 тыс.
A18: 04 Каркас и перекрытия | B18: Зимнее бетонирование (прогрев, тепляк) — если перекрытие попадает на ноябрь–март | C18: м² | D18: 798.74 | E18: 0 | F18: =H18*0.3 | G18: =H18-F18 | H18: =D18*E18 | I18: B, C — бетонирование в тёплый сезон по ПОС
A19: 04 Каркас и перекрытия | B19: Армопояса, перемычки, монолитные участки | C19: м³ | D19: 40 | E19: 30000 | F19: =H19*0.55 | G19: =H19-F19 | H19: =D19*E19 | I19: рынок МО
A20: 04 Каркас и перекрытия | B20: Монолитная лестница 012 с ограждением | C20: компл | D20: 1 | E20: 600000 | F20: =H20*0.5 | G20: =H20-F20 | H20: =D20*E20 | I20: 1 лестница 2 марша
A21: 05 Стены и перегородки | B21: Наружные стены газобетон D500 400 мм (блок, клей, армирование, кладка) | C21: м³ | D21: 309.14 | E21: 13000 | F21: =H21*0.6 | G21: =H21-F21 | H21: =D21*E21 | I21: рынок 11,5–15,5 тыс.
A22: 05 Стены и перегородки | B22: Внутренние стены газобетон 300 мм | C22: м³ | D22: 153.54 | E22: 13000 | F22: =H22*0.6 | G22: =H22-F22 | H22: =D22*E22 | I22: рынок 11,5–15,5 тыс.
A23: 05 Стены и перегородки | B23: Перегородки газобетон 150 мм | C23: м³ | D23: 57.47 | E23: 14000 | F23: =H23*0.6 | G23: =H23-F23 | H23: =D23*E23 | I23: мелкий блок дороже на м³
A24: 05 Стены и перегородки | B24: Противопожарные стены гараж/лестница, тамбур-шлюз (EI 150, двери EI 60) | C24: компл | D24: 1 | E24: 450000 | F24: =H24*0.6 | G24: =H24-F24 | H24: =D24*E24 | I24: СП 4.13130 — требование раздела ПБ
A25: 06 Кровля | B25: Чердачное перекрытие деревянное утеплённое 250 мм | C25: м² | D25: 473.73 | E25: 7000 | F25: =H25*0.6 | G25: =H25-F25 | H25: =D25*E25 | I25: рынок 6–8,5 тыс.
A26: 06 Кровля | B26: Скатная кровля: стропила, ОСП, мембраны, кликфальц, водосток, снегозадержание | C26: м² | D26: 570.93 | E26: 10000 | F26: =H26*0.6 | G26: =H26-F26 | H26: =D26*E26 | I26: рынок 9–13 тыс.; СХ 19,6 тыс.
A27: 06 Кровля | B27: Плоская кровля: эксплуатируемая (A, B) / неэксплуатируемая (C) | C27: м² | D27: 233.34 | E27: 8000 | F27: =H27*0.6 | G27: =H27-F27 | H27: =D27*E27 | I27: рынок 9–16 тыс.
A28: 06 Кровля | B28: Каркасные фронтоны | C28: м² | D28: 186.21 | E28: 5500 | F28: =H28*0.6 | G28: =H28-F28 | H28: =D28*E28 | I28: рынок МО
A29: 07 Фасады | B29: Утепление вентфасада минвата 100 мм + ветрозащита + подсистема | C29: м² | D29: 1310 | E29: 2400 | F29: =H29*0.55 | G29: =H29-F29 | H29: =D29*E29 | I29: подсистема 1,2–1,5 + утеплитель 1,0
A30: 07 Фасады | B30: Облицовка натуральным сланцем (A 490 м²; B, C — акцент 150 м²) | C30: м² | D30: 490 | E30: 0 | F30: =H30*0.6 | G30: =H30-F30 | H30: =D30*E30 | I30: рынок 8–13 тыс.
A31: 07 Фасады | B31: Облицовка сланцем — акцентные плоскости (вход, торец к воде) | C31: м² | D31: 150 | E31: 10500 | F31: =H31*0.6 | G31: =H31-F31 | H31: =D31*E31 | I31: рычаг 3
A32: 07 Фасады | B32: Планкен лиственница с обработкой (A 600 м²; B, C — 940 м²) | C32: м² | D32: 600 | E32: 0 | F32: =H32*0.6 | G32: =H32-F32 | H32: =D32*E32 | I32: рынок 6,4–9,9 тыс.
A33: 07 Фасады | B33: Планкен лиственница с обработкой — основной материал | C33: м² | D33: 940 | E33: 6000 | F33: =H33*0.6 | G33: =H33-F33 | H33: =D33*E33 | I33: рычаг 3
A34: 07 Фасады | B34: Фасадный фальц | C34: м² | D34: 220 | E34: 5500 | F34: =H34*0.6 | G34: =H34-F34 | H34: =D34*E34 | I34: рынок 4,5–7,5 тыс.
A35: 07 Фасады | B35: Цоколь: облицовка, отмостка 1,0 м с утеплением | C35: м.п. | D35: 104 | E35: 8000 | F35: =H35*0.55 | G35: =H35-F35 | H35: =D35*E35 | I35: периметр ≈ 104 м
A36: 08 Окна, витражи, ворота | B36: Тёплые алюминиевые витражи: Schüco-уровень (A) / Alutech W72 (B, C) | C36: м² | D36: 170.64 | E36: 22000 | F36: =H36*0.75 | G36: =H36-F36 | H36: =D36*E36 | I36: Alutech под ключ 19–27 тыс.
A37: 08 Окна, витражи, ворота | B37: Окна ПВХ (Rehau/Veka класс А, R 0,8) | C37: м² | D37: 60 | E37: 14000 | F37: =H37*0.75 | G37: =H37-F37 | H37: =D37*E37 | I37: рынок 12–18 тыс.
A38: 08 Окна, витражи, ворота | B38: Откосы, отливы, подоконники | C38: м² | D38: 230.64 | E38: 2000 | F38: =H38*0.5 | G38: =H38-F38 | H38: =D38*E38 | I38: рынок МО
A39: 08 Окна, витражи, ворота | B39: Ворота гаражные секционные утеплённые с автоматикой 3.5×2.6 м | C39: шт | D39: 8 | E39: 200000 | F39: =H39*0.85 | G39: =H39-F39 | H39: =D39*E39 | I39: Doorhan/Alutech с приводом
A40: 08 Окна, витражи, ворота | B40: Ворота эллинга подъёмно-секционные (под катер на прицепе) 4.5×3.6 м | C40: шт | D40: 1 | E40: 520000 | F40: =H40*0.85 | G40: =H40-F40 | H40: =D40*E40 | I40: нестандарт, усиленный привод
...

Sheet Вне СМР
A1: Раздел | B1: Наименование | C1: A | D1: B | E1: C | F1: Комментарий
A2: 20 Проектирование и изыскания | B2: Инженерно-геологические изыскания на пятне (4 скважины по 15 м, лаборатория) | C2: 450000 | D2: 400000 | E2: 400000 | F2: до КР фундамента
A3: 20 Проектирование и изыскания | B3: Рабочая документация АР + КР (КЖ, КД) + ИОС + ПБ | C3: 3400000 | D3: 2900000 | E3: 2600000 | F3: 3,0 тыс. ₽/м²
A4: 20 Проектирование и изыскания | B4: Авторский надзор архитектора и конструктора | C4: 450000 | D4: 350000 | E4: 300000 | F4: 12 мес
A5: 20 Проектирование и изыскания | B5: Технический надзор заказчика (≈ 1,5 % СМР) | C5: 1900000 | D5: 1500000 | E5: 1300000 | F5: независимый
A6: 20 Проектирование и изыскания | B6: Негосударственная экспертиза КР и ПБ (добровольная) | C6: 450000 | D6: 400000 | E6: 0 | F6: рекомендуется
A7: 21 Право и регистрация | B7: Юрист: ВОЗ/прибрежная полоса, капитальность в 100-м зоне, ЗСО | C7: 350000 | D7: 300000 | E7: 300000 | F7: поручение Сычёву
A8: 21 Право и регистрация | B8: Техплан, постановка на кадастровый учёт, регистрация | C8: 90000 | D8: 90000 | E8: 90000 | F8: ≈ 45 тыс. ₽ (19.10)
A9: 22 Наружные сети и благоустройство | B9: Подключение к посёлковым сетям: кабель 0,4 кВ, В1, К1, связь (≈ 80 м) | C9: 2200000 | D9: 1800000 | E9: 1800000 | F9: от точек посёлковых сетей
A10: 22 Наружные сети и благоустройство | B10: Площадки у ворот, гостевая парковка, навес, разворот (≈ 650 м² плитка/асфальт) | C10: 4200000 | D10: 3300000 | E10: 2200000 | F10: по генплану Спицыной
A11: 22 Наружные сети и благоустройство | B11: Ливневая канализация с ЛОС участка эллинга | C11: 900000 | D11: 800000 | E11: 800000 | F11: ВОЗ: очистка обязательна
A12: 22 Наружные сети и благоустройство | B12: Дорога эллинг — пирс (≈ 120 м, щебёночное/асфальт) | C12: 1500000 | D12: 1200000 | E12: 0 | F12: ПОЛ по :469 — до 30.11
A13: 23 Оснащение | B13: Оборудование спортзала (по ТЗ интересантов) | C13: 5000000 | D13: 4000000 | E13: 4000000 | F13: без лимита — оценка
... A16: 24 Причал (вне здания) | B16: Сборный понтон 2×(3×12 м) с трапом и швартовкой (база ГИМС) | C16: 5500000 | D16: 4500000 | E16: 0 | F16: не регистрируется; зимой лежит на дне

Sheet По разделам
A1: Раздел | B1: A | C1: B | D1: C | E1: B, ₽/м²
A2: 01 Подготовка территории | B2: 2110000 | C2: 1420000 | D2: 1420000 | E2: 1477
A3: 02 Земляные работы | B3: 1017600 | C3: 896400 | D3: 896400 | E3: 932
A4: 03 Фундамент | B4: 13254324 | C4: 8438449 | D4: 8438449 | E4: 8776
A5: 04 Каркас и перекрытия | B5: 14774376 | C5: 11895510 | D5: 8141432 | E5: 12371
A6: 05 Стены и перегородки | B6: 7558230 | C6: 7269420 | D6: 7269420 | E6: 7560
A7: 06 Кровля | B7: 14104128 | C7: 13537245 | D7: 11916285 | E7: 14079
A8: 07 Фасады | B8: 14817000 | C8: 12683000 | D8: 12401000 | E8: 13190
A9: 08 Окна, витражи, ворота | B9: 10937720 | C9: 8206000 | D9: 7815360 | E9: 8534
A10: 09 Наружные МК | B10: 3150000 | C10: 2350000 | D10: 1750000 | E10: 2444
A11: 10 Отделка черновая | B11: 10961556 | C11: 7119608 | D11: 7005905 | E11: 7404
A12: 11 Отделка чистовая | B12: 24932729 | C12: 12267645 | D12: 5150820 | E12: 12758
A13: 12 Отопление (ОВ) | B13: 7258578 | C13: 6117819 | D13: 6017819 | E13: 6363
... A17: 16 Слаботочные системы и пожарная безопасность (СС, ПБ) | B17: 4871155 | C17: 3575001 | D17: 3175001 | E17: 3718

Sheet Допущения
A1: Площади помещений — по экспликациям АР-концепта: 1 этаж ред. 01.09 (416,33 м²), 2 этаж ред. 31.07 (545,21 м²), итого 961,54 м². Смета ЭП считала 964,60 м² (иная редакция) — разница 0,3 %.
A2: Объёмы конструкций (перекрытия, кладка, кровли, фасады, остекление) — из сметы ЭП, лист «Исходные данные».
A3: Высоты этажей: 1 этаж 4,30 м (гаражи, ворота 2,6 м, катер на прицепе), 2 этаж 3,10 м; конёк +10,73.
A4: Ворота: 8 гаражных 3,5×2,6 м и 1 эллинговые 4,5×3,6 м — размеры по сетке осей (шаг 4 475 + 825), уточнить по ведомости проёмов архитектора.
A5: Геологии на пятне нет. Принят суглинок/глина ≈ 3 м по данным совещания 05.10 и ИГИ участков; несущая способность сваи 380 кН — до испытаний.
A6: Газа нет до 2028 г.; основной источник тепла — пеллеты с резервным электрокотлом, переход на газ заложен (как в доме «Ромарио»).
A7: Цены — Москва и МО, IV кв. 2026, с НДС, «под ключ» (материал + работа + доставка + накладные подрядчика).
A8: Файл по ссылке Dropbox от 23.10.2026 из окружения недоступен (хост заблокирован сетевой политикой) — при его получении сверить экспликацию, проёмы и ворота (см. записку).
